Workbook
Name _ftn1: Summary!$I$5
Name _ftn2: Summary!$I$6
Name _ftn3: Summary!$I$7

Sheet Insights
A1: Strategy Insights | S&P 500 Comparison
A2: October 31, 2000–July 31, 2026 | 310 matched monthly observations | J2: Date | K2: S&P 500 Growth | L2: Leveraged Strategy Growth | M2: S&P Peak | N2: S&P Drawdown | O2: Strategy Drawdown
J3: =Summary!A2 -> 36830 | K3: =1+Summary!B2 -> 0.99069493 | L3: =1+Summary!E2 -> 1.0130587 | M3: =K3 -> 0.99069493 | N3: =K3/M3-1 -> 0 | O3: =L3/MAX($L$3:L3)-1 -> 0
A4: STORY IN BRIEF | J4: =Summary!A3 -> 36860 | K4: =K3*(1+Summary!B3) -> 0.90901706 | L4: =L3*(1+Summary!E3) -> 0.99637418 | M4: =MAX($K$3:K4) -> 0.99069493 | N4: =K4/M4-1 -> -0.082445024 | O4: =L4/MAX($L$3:L4)-1 -> -0.016469498
A5: ="The leveraged strategy generated "&TEXT(C11,"0.0%")&" annualized versus "&TEXT(B11,"0.0%")&" for the S&P 500 while running slightly lower volatility. Its maximum drawdown was "&TEXT(C14,"0.0%")&" versus "&TEXT(B14,"0.0%")&", and it lost less on average in the 118 months when the S&P 500 declined. The advantage is economically meaningful, but it depends on a 3.9x leverage assumption and should be stress-tested for costs and implementation constraints." -> The leveraged strategy generated 17.4% annualized versus 7.8% for the S&P 500 while running slightly lower volatility. Its maximum drawdown was -30.0% versus -56.1%, and it lost less on average in the 118 months when the S&P 500 declined. The advantage is economically meaningful, but it depends on a 3.9x leverage assumption and should be stress-tested for costs and implementation constraints. | J5: =Summary!A4 -> 36891 | K5: =K4*(1+Summary!B4) -> 0.90488147 | L5: =L4*(1+Summary!E4) -> 1.0044362 | M5: =MAX($K$3:K5) -> 0.99069493 | N5: =K5/M5-1 -> -0.086619456 | O5: =L5/MAX($L$3:L5)-1 -> -0.0085113672
J6: =Summary!A5 -> 36922 | K6: =K5*(1+Summary!B5) -> 0.93065505 | L6: =L5*(1+Summary!E5) -> 1.0394595 | M6: =MAX($K$3:K6) -> 0.99069493 | N6: =K6/M6-1 -> -0.060603802 | O6: =L6/MAX($L$3:L6)-1 -> 0
J7: =Summary!A6 -> 36950 | K7: =K6*(1+Summary!B6) -> 0.8418876 | L7: =L6*(1+Summary!E6) -> 1.0440065 | M7: =MAX($K$3:K7) -> 0.99069493 | N7: =K7/M7-1 -> -0.15020499 | O7: =L7/MAX($L$3:L7)-1 -> 0
J8: =Summary!A7 -> 36981 | K8: =K7*(1+Summary!B7) -> 0.78428476 | L8: =L7*(1+Summary!E7) -> 1.0713476 | M8: =MAX($K$3:K8) -> 0.99069493 | N8: =K8/M8-1 -> -0.20834886 | O8: =L8/MAX($L$3:L8)-1 -> 0
A9: PERFORMANCE AND RISK SCORECARD | J9: =Summary!A8 -> 37011 | K9: =K8*(1+Summary!B8) -> 0.8412968 | L9: =L8*(1+Summary!E8) -> 1.0821366 | M9: =MAX($K$3:K9) -> 0.99069493 | N9: =K9/M9-1 -> -0.15080134 | O9: =L9/MAX($L$3:L9)-1 -> 0
A10: Metric | B10: S&P 500 | C10: Leveraged Strategy | D10: Strategy Advantage | J10: =Summary!A9 -> 37042 | K10: =K9*(1+Summary!B9) -> 0.84343845 | L10: =L9*(1+Summary!E9) -> 1.0821152 | M10: =MAX($K$3:K10) -> 0.99069493 | N10: =K10/M10-1 -> -0.14863958 | O10: =L10/MAX($L$3:L10)-1 -> -1.973969e-05
A11: Annualized return | B11: =Summary!V5 -> 0.078300905 | C11: =Summary!X5 -> 0.17377247 | D11: =C11-B11 -> 0.095471566 | J11: =Summary!A10 -> 37072 | K11: =K10*(1+Summary!B10) -> 0.81965881 | L11: =L10*(1+Summary!E10) -> 1.083072 | M11: =MAX($K$3:K11) -> 0.99069493 | N11: =K11/M11-1 -> -0.17264256 | O11: =L11/MAX($L$3:L11)-1 -> 0
A12: Annualized volatility | B12: =Summary!V6 -> 0.1528659 | C12: =Summary!X6 -> 0.15020709 | D12: =C12-B12 -> -0.0026588145 | J12: =Summary!A11 -> 37103 | K12: =K11*(1+Summary!B11) -> 0.80872905 | L12: =L11*(1+Summary!E11) -> 1.1009857 | M12: =MAX($K$3:K12) -> 0.99069493 | N12: =K12/M12-1 -> -0.18367499 | O12: =L12/MAX($L$3:L12)-1 -> 0
A13: Sharpe ratio | B13: =Summary!V7 -> 0.38732378 | C13: =Summary!X7 -> 1.0297794 | D13: =C13-B13 -> 0.64245562 | J13: =Summary!A12 -> 37134 | K13: =K12*(1+Summary!B12) -> 0.75533565 | L13: =L12*(1+Summary!E12) -> 1.0660052 | M13: =MAX($K$3:K13) -> 0.99069493 | N13: =K13/M13-1 -> -0.23756988 | O13: =L13/MAX($L$3:L13)-1 -> -0.031771926
A14: Maximum drawdown | B14: =MIN(N3:N312) -> -0.56071562 | C14: =MIN(O3:O312) -> -0.30022448 | D14: =C14-B14 -> 0.26049114 | J14: =Summary!A13 -> 37164 | K14: =K13*(1+Summary!B13) -> 0.67683332 | L14: =L13*(1+Summary!E13) -> 1.0324824 | M14: =MAX($K$3:K14) -> 0.99069493 | N14: =K14/M14-1 -> -0.31680954 | O14: =L14/MAX($L$3:L14)-1 -> -0.062219901
A15: Average return in S&P down months | B15: =AVERAGEIF(Summary!B2:B311,"<0",Summary!B2:B311) -> -0.037328582 | C15: =AVERAGEIF(Summary!B2:B311,"<0",Summary!E2:E311) -> -0.017394788 | D15: =C15-B15 -> 0.019933794 | J15: =Summary!A14 -> 37195 | K15: =K14*(1+Summary!B14) -> 0.68783694 | L15: =L14*(1+Summary!E14) -> 1.0626073 | M15: =MAX($K$3:K15) -> 0.99069493 | N15: =K15/M15-1 -> -0.30570257 | O15: =L15/MAX($L$3:L15)-1 -> -0.034858206
A16: Positive in S&P down months | B16: 0 | C16: =COUNTIFS(Summary!B2:B311,"<0",Summary!E2:E311,">0")/COUNTIF(Summary!B2:B311,"<0") -> 0.33050847 | D16: =C16-B16 -> 0.33050847 | J16: =Summary!A15 -> 37225 | K16: =K15*(1+Summary!B15) -> 0.73923639 | L16: =L15*(1+Summary!E15) -> 1.0686098 | M16: =MAX($K$3:K16) -> 0.99069493 | N16: =K16/M16-1 -> -0.25382035 | O16: =L16/MAX($L$3:L16)-1 -> -0.029406297
A17: Correlation with S&P 500 | B17: 1 | C17: =CORREL(Summary!B2:B311,Summary!E2:E311) -> 0.65003735 | D17: =C17-B17 -> -0.34996265 | J17: =Summary!A16 -> 37256 | K17: =K16*(1+Summary!B16) -> 0.74433203 | L17: =L16*(1+Summary!E16) -> 1.0820576 | M17: =MAX($K$3:K17) -> 0.99069493 | N17: =K17/M17-1 -> -0.24867685 | O17: =L17/MAX($L$3:L17)-1 -> -0.017191927
J18: =Summary!A17 -> 37287 | K18: =K17*(1+Summary!B17) -> 0.73222066 | L18: =L17*(1+Summary!E17) -> 1.07248 | M18: =MAX($K$3:K18) -> 0.99069493 | N18: =K18/M18-1 -> -0.26090198 | O18: =L18/MAX($L$3:L18)-1 -> -0.025891034
A19: THREE MOST IMPORTANT TAKEAWAYS | J19: =Summary!A18 -> 37315 | K19: =K18*(1+Summary!B18) -> 0.71700761 | L19: =L18*(1+Summary!E18) -> 1.1014785 | M19: =MAX($K$3:K19) -> 0.99069493 | N19: =K19/M19-1 -> -0.27625792 | O19: =L19/MAX($L$3:L19)-1 -> 0
A20: ="1 | Return efficiency — The leveraged strategy delivered "&TEXT(C11,"0.0%")&" annualized return at "&TEXT(C12,"0.0%")&" volatility, compared with "&TEXT(B11,"0.0%")&" return and "&TEXT(B12,"0.0%")&" volatility for the S&P 500; its Sharpe ratio was "&TEXT(C13,"0.00")&" versus "&TEXT(B13,"0.00")&"." -> 1 | Return efficiency — The leveraged strategy delivered 17.4% annualized return at 15.0% volatility, compared with 7.8% return and 15.3% volatility for the S&P 500; its Sharpe ratio was 1.03 versus 0.39. | J20: =Summary!A19 -> 37346 | K20: =K19*(1+Summary!B19) -> 0.74263348 | L20: =L19*(1+Summary!E19) -> 1.0910694 | M20: =MAX($K$3:K20) -> 0.99069493 | N20: =K20/M20-1 -> -0.25039135 | O20: =L20/MAX($L$3:L20)-1 -> -0.0094500869
J21: =Summary!A20 -> 37376 | K21: =K20*(1+Summary!B20) -> 0.69610812 | L21: =L20*(1+Summary!E20) -> 1.0860984 | M21: =MAX($K$3:K21) -> 0.99069493 | N21: =K21/M21-1 -> -0.29735371 | O21: =L21/MAX($L$3:L21)-1 -> -0.013963096
A22: ="2 | Drawdown control — Maximum drawdown improved from "&TEXT(B14,"0.0%")&" for the S&P 500 to "&TEXT(C14,"0.0%")&" for the leveraged strategy, a "&TEXT(D14,"0.0%")&" reduction in drawdown depth." -> 2 | Drawdown control — Maximum drawdown improved from -56.1% for the S&P 500 to -30.0% for the leveraged strategy, a 26.0% reduction in drawdown depth. | J22: =Summary!A21 -> 37407 | K22: =K21*(1+Summary!B21) -> 0.68983088 | L22: =L21*(1+Summary!E21) -> 1.1168028 | M22: =MAX($K$3:K22) -> 0.99069493 | N22: =K22/M22-1 -> -0.3036899 | O22: =L22/MAX($L$3:L22)-1 -> 0
J23: =Summary!A22 -> 37437 | K23: =K22*(1+Summary!B22) -> 0.63909608 | L23: =L22*(1+Summary!E22) -> 1.0749342 | M23: =MAX($K$3:K23) -> 0.99069493 | N23: =K23/M23-1 -> -0.35490123 | O23: =L23/MAX($L$3:L23)-1 -> -0.037489675
A24: ="3 | Down-market resilience — Across "&COUNTIF(Summary!B2:B311,"<0")&" negative S&P months, the index averaged "&TEXT(B15,"0.0%")&" while the leveraged strategy averaged "&TEXT(C15,"0.0%")&" and produced a positive return in "&TEXT(C16,"0.0%")&" of those months." -> 3 | Down-market resilience — Across 118 negative S&P months, the index averaged -3.7% while the leveraged strategy averaged -1.7% and produced a positive return in 33.1% of those months. | J24: =Summary!A23 -> 37468 | K24: =K23*(1+Summary!B23) -> 0.58843512 | L24: =L23*(1+Summary!E23) -> 1.046335 | M24: =MAX($K$3:K24) -> 0.99069493 | N24: =K24/M24-1 -> -0.40603802 | O24: =L24/MAX($L$3:L24)-1 -> -0.063097796
J25: =Summary!A24 -> 37499 | K25: =K24*(1+Summary!B24) -> 0.59131526 | L25: =L24*(1+Summary!E24) -> 1.0894681 | M25: =MAX($K$3:K25) -> 0.99069493 | N25: =K25/M25-1 -> -0.40313082 | O25: =L25/MAX($L$3:L25)-1 -> -0.024475868
J26: =Summary!A25 -> 37529 | K26: =K25*(1+Summary!B25) -> 0.5259582 | L26: =L25*(1+Summary!E25) -> 1.0827966 | M26: =MAX($K$3:K26) -> 0.99069493 | N26: =K26/M26-1 -> -0.46910175 | O26: =L26/MAX($L$3:L26)-1 -> -0.030449574
J27: =Summary!A26 -> 37560 | K27: =K26*(1+Summary!B26) -> 0.57144967 | L27: =L26*(1+Summary!E26) -> 1.1008863 | M27: =MAX($K$3:K27) -> 0.99069493 | N27: =K27/M27-1 -> -0.423183 | O27: =L27/MAX($L$3:L27)-1 -> -0.014251819
J28: =Summary!A27 -> 37590 | K28: =K27*(1+Summary!B27) -> 0.60409128 | L28: =L27*(1+Summary!E27) -> 1.1067904 | M28: =MAX($K$3:K28) -> 0.99069493 | N28: =K28/M28-1 -> -0.39023481 | O28: =L28/MAX($L$3:L28)-1 -> -0.0089652741
J29: =Summary!A28 -> 37621 | K29: =K28*(1+Summary!B28) -> 0.56790488 | L29: =L28*(1+Summary!E28) -> 1.1565423 | M29: =MAX($K$3:K29) -> 0.99069493 | N29: =K29/M29-1 -> -0.42676109 | O29: =L29/MAX($L$3:L29)-1 -> 0
J30: =Summary!A29 -> 37652 | K30: =K29*(1+Summary!B29) -> 0.55224873 | L30: =L29*(1+Summary!E29) -> 1.172964 | M30: =MAX($K$3:K30) -> 0.99069493 | N30: =K30/M30-1 -> -0.44256429 | O30: =L30/MAX($L$3:L30)-1 -> 0
J31: =Summary!A30 -> 37680 | K31: =K30*(1+Summary!B30) -> 0.54338675 | L31: =L30*(1+Summary!E30) -> 1.1960298 | M31: =MAX($K$3:K31) -> 0.99069493 | N31: =K31/M31-1 -> -0.4515095 | O31: =L31/MAX($L$3:L31)-1 -> 0
J32: =Summary!A31 -> 37711 | K32: =K31*(1+Summary!B31) -> 0.54803929 | L32: =L31*(1+Summary!E31) -> 1.1648007 | M32: =MAX($K$3:K32) -> 0.99069493 | N32: =K32/M32-1 -> -0.44681327 | O32: =L32/MAX($L$3:L32)-1 -> -0.026110619
J33: =Summary!A32 -> 37741 | K33: =K32*(1+Summary!B32) -> 0.59271841 | L33: =L32*(1+Summary!E32) -> 1.2017545 | M33: =MAX($K$3:K33) -> 0.99069493 | N33: =K33/M33-1 -> -0.4017145 | O33: =L33/MAX($L$3:L33)-1 -> 0
J34: =Summary!A33 -> 37772 | K34: =K33*(1+Summary!B33) -> 0.62329222 | L34: =L33*(1+Summary!E33) -> 1.2956676 | M34: =MAX($K$3:K34) -> 0.99069493 | N34: =K34/M34-1 -> -0.37085352 | O34: =L34/MAX($L$3:L34)-1 -> 0
J35: =Summary!A34 -> 37802 | K35: =K34*(1+Summary!B34) -> 0.6305295 | L35: =L34*(1+Summary!E34) -> 1.2429524 | M35: =MAX($K$3:K35) -> 0.99069493 | N35: =K35/M35-1 -> -0.36354827 | O35: =L35/MAX($L$3:L35)-1 -> -0.040685768
J36: =Summary!A35 -> 37833 | K36: =K35*(1+Summary!B35) -> 0.64094232 | L36: =L35*(1+Summary!E35) -> 1.2345351 | M36: =MAX($K$3:K36) -> 0.99069493 | N36: =K36/M36-1 -> -0.35303764 | O36: =L36/MAX($L$3:L36)-1 -> -0.047182204
J37: =Summary!A36 -> 37864 | K37: =K36*(1+Summary!B36) -> 0.65290599 | L37: =L36*(1+Summary!E36) -> 1.220195 | M37: =MAX($K$3:K37) -> 0.99069493 | N37: =K37/M37-1 -> -0.34096161 | O37: =L37/MAX($L$3:L37)-1 -> -0.058249949
A38: DATA QUALITY AND INTERPRETATION | J38: =Summary!A37 -> 37894 | K38: =K37*(1+Summary!B37) -> 0.64493021 | L38: =L37*(1+Summary!E37) -> 1.245721 | M38: =MAX($K$3:K38) -> 0.99069493 | N38: =K38/M38-1 -> -0.3490123 | O38: =L38/MAX($L$3:L38)-1 -> -0.038548896
A39: The confirmed period contains 310 matched monthly observations in the core price, return, trend, and strategy series. One existing formula error remains in Summary!J2 because its RANK formula evaluates the text value in Summary!G2 against Nasdaq returns; that field is not used in this analysis. Earlier-history source errors fall outside the selected window, but the leveraged result assumes 3.9x exposure and the workbook does not visibly model transaction costs, financing slippage, or capacity constraints. | J39: =Summary!A38 -> 37925 | K39: =K38*(1+Summary!B38) -> 0.68096891 | L39: =L38*(1+Summary!E38) -> 1.3222875 | M39: =MAX($K$3:K39) -> 0.99069493 | N39: =K39/M39-1 -> -0.31263511 | O39: =L39/MAX($L$3:L39)-1 -> 0
J40: =Summary!A39 -> 37955 | K40: =K39*(1+Summary!B39) -> 0.68628609 | L40: =L39*(1+Summary!E39) -> 1.3358062 | M40: =MAX($K$3:K40) -> 0.99069493 | N40: =K40/M40-1 -> -0.30726798 | O40: =L40/MAX($L$3:L40)-1 -> 0
...

Sheet Trend Insights
A1: Trend Return Insights | S&P 500 Benchmark
A2: October 31, 2000–July 31, 2026 | 310 matched monthly observations | J2: Date | K2: S&P 500 | L2: Trend Return | M2: Trend Levered Return | N2: S&P Peak | O2: Trend Peak | P2: S&P DD | Q2: Trend DD | R2: Trend Levered DD | T2: Date | U2: GSCI Gasoil | V2: GSCI Gold | W2: Japan Gov’t Bond | X2: US 10Y Gov’t Bond | Y2: S&P 500 | Z2: Nasdaq 100 | AA2: JPY/USD | AB2: EUR/USD | AC2: Sleeve Sum | AD2: Trend Levered Return | AE2: Difference | AF2: Log Growth | AH2: Event Start | AI2: Event End
J3: =Summary!A2 -> 36830 | K3: =1+Summary!B2 -> 0.99069493 | L3: =1+Summary!H2 -> 1.0064456 | M3: =1+Summary!I2 -> 1.0272006 | N3: =K3 -> 0.99069493 | O3: =L3 -> 1.0064456 | P3: =K3/N3-1 -> 0 | Q3: =L3/O3-1 -> 0 | R3: =M3/MAX($M$3:M3)-1 -> 0 | T3: =Summary!A2 -> 36830 | U3: =Trend_Simulation!B98*Trend_Simulation!K98*4.31 -> -0.0021680541 | V3: =Trend_Simulation!C98*Trend_Simulation!L98*4.31 -> 0.019020215 | W3: =Trend_Simulation!D98*Trend_Simulation!M98*4.31 -> 0.012197079 | X3: =Trend_Simulation!E98*Trend_Simulation!N98*4.31 -> 0.0044703058 | Y3: =Trend_Simulation!F98*Trend_Simulation!O98*4.31 -> -0.0028215034 | Z3: =Trend_Simulation!G98*Trend_Simulation!P98*4.31 -> -0.010853795 | AA3: =Trend_Simulation!H98*Trend_Simulation!Q98*4.31 -> 0.0079364158 | AB3: =Trend_Simulation!#REF!*Trend_Simulation!#REF!*4.31 -> #REF! | AC3: =SUM(U3:AB3) -> #REF! | AD3: =Summary!I2 -> 0.027200557 | AE3: =AC3-AD3 -> #REF! | AF3: =LN(1+AD3) -> 0.026837196 | AH3: 36830 | AI3: 37621
A4: STORY IN BRIEF | J4: =Summary!A3 -> 36860 | K4: =K3*(1+Summary!B3) -> 0.90901706 | L4: =L3*(1+Summary!H3) -> 1.0212136 | M4: =M3*(1+Summary!I3) -> 1.0908068 | N4: =MAX($K$3:K4) -> 0.99069493 | O4: =MAX($L$3:L4) -> 1.0212136 | P4: =K4/N4-1 -> -0.082445024 | Q4: =L4/O4-1 -> 0 | R4: =M4/MAX($M$3:M4)-1 -> 0 | T4: =Summary!A3 -> 36860 | U4: =Trend_Simulation!B99*Trend_Simulation!K99*4.31 -> 0.015564116 | V4: =Trend_Simulation!C99*Trend_Simulation!L99*4.31 -> -0.0079689133 | W4: =Trend_Simulation!D99*Trend_Simulation!M99*4.31 -> 0.028755084 | X4: =Trend_Simulation!E99*Trend_Simulation!N99*4.31 -> 0.020263531 | Y4: =Trend_Simulation!F99*Trend_Simulation!O99*4.31 -> 0.024999149 | Z4: =Trend_Simulation!G99*Trend_Simulation!P99*4.31 -> -0.0285683 | AA4: =Trend_Simulation!H99*Trend_Simulation!Q99*4.31 -> 0.010197851 | AB4: =Trend_Simulation!#REF!*Trend_Simulation!#REF!*4.31 -> #REF! | AC4: =SUM(U4:AB4) -> #REF! | AD4: =Summary!I3 -> 0.061921908 | AE4: =AC4-AD4 -> #REF! | AF4: =LN(1+AD4) -> 0.060080387 | AH4: 37652 | AI4: 39416
A5: ="Unlevered trend produced "&TEXT(C11,"0.0%")&" annualized with only "&TEXT(C12,"0.0%")&" volatility and a "&TEXT(C14,"0.0%")&" maximum drawdown. At approximately 4.3x leverage, trend delivered "&TEXT(D11,"0.0%")&" annualized at volatility similar to the S&P 500, while retaining negative equity correlation and a shallower drawdown. The strongest evidence is crisis resilience: leveraged trend averaged "&TEXT(D15,"0.0%")&" in negative S&P months and "&TEXT(D17,"0.0%")&" when the S&P fell at least 5%." -> Unlevered trend produced 5.6% annualized with only 3.6% volatility and a -5.9% maximum drawdown. At approximately 4.3x leverage, trend delivered 17.1% annualized at volatility similar to the S&P 500, while retaining negative equity correlation and a shallower drawdown. The strongest evidence is crisis resilience: leveraged trend averaged 1.5% in negative S&P months and 3.6% when the S&P fell at least 5%. | J5: =Summary!A4 -> 36891 | K5: =K4*(1+Summary!B4) -> 0.90488147 | L5: =L4*(1+Summary!H4) -> 1.0249374 | M5: =M4*(1+Summary!I4) -> 1.1075918 | N5: =MAX($K$3:K5) -> 0.99069493 | O5: =MAX($L$3:L5) -> 1.0249374 | P5: =K5/N5-1 -> -0.086619456 | Q5: =L5/O5-1 -> 0 | R5: =M5/MAX($M$3:M5)-1 -> 0 | T5: =Summary!A4 -> 36891 | U5: =Trend_Simulation!B100*Trend_Simulation!K100*4.31 -> -0.028700111 | V5: =Trend_Simulation!C100*Trend_Simulation!L100*4.31 -> -0.00055194019 | W5: =Trend_Simulation!D100*Trend_Simulation!M100*4.31 -> -0.00018099217 | X5: =Trend_Simulation!E100*Trend_Simulation!N100*4.31 -> 0.016416674 | Y5: =Trend_Simulation!F100*Trend_Simulation!O100*4.31 -> 0.0013795137 | Z5: =Trend_Simulation!G100*Trend_Simulation!P100*4.31 -> 0.0094796628 | AA5: =Trend_Simulation!H100*Trend_Simulation!Q100*4.31 -> 0.017873055 | AB5: =Trend_Simulation!#REF!*Trend_Simulation!#REF!*4.31 -> #REF! | AC5: =SUM(U5:AB5) -> #REF! | AD5: =Summary!I4 -> 0.015387689 | AE5: =AC5-AD5 -> #REF! | AF5: =LN(1+AD5) -> 0.015270499 | AH5: 39447 | AI5: 39994
J6: =Summary!A5 -> 36922 | K6: =K5*(1+Summary!B5) -> 0.93065505 | L6: =L5*(1+Summary!H5) -> 1.0295976 | M6: =M5*(1+Summary!I5) -> 1.1288438 | N6: =MAX($K$3:K6) -> 0.99069493 | O6: =MAX($L$3:L6) -> 1.0295976 | P6: =K6/N6-1 -> -0.060603802 | Q6: =L6/O6-1 -> 0 | R6: =M6/MAX($M$3:M6)-1 -> 0 | T6: =Summary!A5 -> 36922 | U6: =Trend_Simulation!B101*Trend_Simulation!K101*4.31 -> -0.015884626 | V6: =Trend_Simulation!C101*Trend_Simulation!L101*4.31 -> 0.014507765 | W6: =Trend_Simulation!D101*Trend_Simulation!M101*4.31 -> 0.027039364 | X6: =Trend_Simulation!E101*Trend_Simulation!N101*4.31 -> 0.0031707392 | Y6: =Trend_Simulation!F101*Trend_Simulation!O101*4.31 -> -0.008636619 | Z6: =Trend_Simulation!G101*Trend_Simulation!P101*4.31 -> -0.012194475 | AA6: =Trend_Simulation!H101*Trend_Simulation!Q101*4.31 -> 0.011594632 | AB6: =Trend_Simulation!#REF!*Trend_Simulation!#REF!*4.31 -> #REF! | AC6: =SUM(U6:AB6) -> #REF! | AD6: =Summary!I5 -> 0.019187567 | AE6: =AC6-AD6 -> #REF! | AF6: =LN(1+AD6) -> 0.019005807 | AH6: 40025 | AI6: 41274
J7: =Summary!A6 -> 36950 | K7: =K6*(1+Summary!B6) -> 0.8418876 | L7: =L6*(1+Summary!H6) -> 1.0537792 | M7: =M6*(1+Summary!I6) -> 1.2407266 | N7: =MAX($K$3:K7) -> 0.99069493 | O7: =MAX($L$3:L7) -> 1.0537792 | P7: =K7/N7-1 -> -0.15020499 | Q7: =L7/O7-1 -> 0 | R7: =M7/MAX($M$3:M7)-1 -> 0 | T7: =Summary!A6 -> 36950 | U7: =Trend_Simulation!B102*Trend_Simulation!K102*4.31 -> 0.0047489551 | V7: =Trend_Simulation!C102*Trend_Simulation!L102*4.31 -> 0.00037465221 | W7: =Trend_Simulation!D102*Trend_Simulation!M102*4.31 -> 0.018579521 | X7: =Trend_Simulation!E102*Trend_Simulation!N102*4.31 -> 0.0094718755 | Y7: =Trend_Simulation!F102*Trend_Simulation!O102*4.31 -> 0.028921829 | Z7: =Trend_Simulation!G102*Trend_Simulation!P102*4.31 -> 0.032730728 | AA7: =Trend_Simulation!H102*Trend_Simulation!Q102*4.31 -> 0.0063989733 | AB7: =Trend_Simulation!#REF!*Trend_Simulation!#REF!*4.31 -> #REF! | AC7: =SUM(U7:AB7) -> #REF! | AD7: =Summary!I6 -> 0.099112756 | AE7: =AC7-AD7 -> #REF! | AF7: =LN(1+AD7) -> 0.094503269 | AH7: 41305 | AI7: 43830
J8: =Summary!A7 -> 36981 | K8: =K7*(1+Summary!B7) -> 0.78428476 | L8: =L7*(1+Summary!H7) -> 1.0786905 | M8: =M7*(1+Summary!I7) -> 1.3645027 | N8: =MAX($K$3:K8) -> 0.99069493 | O8: =MAX($L$3:L8) -> 1.0786905 | P8: =K8/N8-1 -> -0.20834886 | Q8: =L8/O8-1 -> 0 | R8: =M8/MAX($M$3:M8)-1 -> 0 | T8: =Summary!A7 -> 36981 | U8: =Trend_Simulation!B103*Trend_Simulation!K103*4.31 -> -0.0069272915 | V8: =Trend_Simulation!C103*Trend_Simulation!L103*4.31 -> 0.019275152 | W8: =Trend_Simulation!D103*Trend_Simulation!M103*4.31 -> 0.0095452265 | X8: =Trend_Simulation!E103*Trend_Simulation!N103*4.31 -> 0.0023190012 | Y8: =Trend_Simulation!F103*Trend_Simulation!O103*4.31 -> 0.020746771 | Z8: =Trend_Simulation!G103*Trend_Simulation!P103*4.31 -> 0.021993038 | AA8: =Trend_Simulation!H103*Trend_Simulation!Q103*4.31 -> 0.034936676 | AB8: =Trend_Simulation!#REF!*Trend_Simulation!#REF!*4.31 -> #REF! | AC8: =SUM(U8:AB8) -> #REF! | AD8: =Summary!I7 -> 0.099760969 | AE8: =AC8-AD8 -> #REF! | AF8: =LN(1+AD8) -> 0.095092856 | AH8: 43861 | AI8: 43951
A9: PERFORMANCE AND RISK SCORECARD | J9: =Summary!A8 -> 37011 | K9: =K8*(1+Summary!B8) -> 0.8412968 | L9: =L8*(1+Summary!H8) -> 1.0647233 | M9: =M8*(1+Summary!I8) -> 1.2899439 | N9: =MAX($K$3:K9) -> 0.99069493 | O9: =MAX($L$3:L9) -> 1.0786905 | P9: =K9/N9-1 -> -0.15080134 | Q9: =L9/O9-1 -> -0.012948277 | R9: =M9/MAX($M$3:M9)-1 -> -0.054641728 | T9: =Summary!A8 -> 37011 | U9: =Trend_Simulation!B104*Trend_Simulation!K104*4.31 -> 0.020004171 | V9: =Trend_Simulation!C104*Trend_Simulation!L104*4.31 -> -0.010062235 | W9: =Trend_Simulation!D104*Trend_Simulation!M104*4.31 -> 0.0037111662 | X9: =Trend_Simulation!E104*Trend_Simulation!N104*4.31 -> -0.021091457 | Y9: =Trend_Simulation!F104*Trend_Simulation!O104*4.31 -> -0.02204213 | Z9: =Trend_Simulation!G104*Trend_Simulation!P104*4.31 -> -0.020945012 | AA9: =Trend_Simulation!H104*Trend_Simulation!Q104*4.31 -> -0.0053815765 | AB9: =Trend_Simulation!#REF!*Trend_Simulation!#REF!*4.31 -> #REF! | AC9: =SUM(U9:AB9) -> #REF! | AD9: =Summary!I8 -> -0.054641728 | AE9: =AC9-AD9 -> #REF! | AF9: =LN(1+AD9) -> -0.056191299 | AH9: 43982 | AI9: 44620
A10: Metric | B10: S&P 500 | C10: Trend Return | D10: Trend Levered Return | J10: =Summary!A9 -> 37042 | K10: =K9*(1+Summary!B9) -> 0.84343845 | L10: =L9*(1+Summary!H9) -> 1.0641298 | M10: =M9*(1+Summary!I9) -> 1.286909 | N10: =MAX($K$3:K10) -> 0.99069493 | O10: =MAX($L$3:L10) -> 1.0786905 | P10: =K10/N10-1 -> -0.14863958 | Q10: =L10/O10-1 -> -0.013498569 | R10: =M10/MAX($M$3:M10)-1 -> -0.056865868 | T10: =Summary!A9 -> 37042 | U10: =Trend_Simulation!B105*Trend_Simulation!K105*4.31 -> -0.00010812901 | V10: =Trend_Simulation!C105*Trend_Simulation!L105*4.31 -> -0.0028996947 | W10: =Trend_Simulation!D105*Trend_Simulation!M105*4.31 -> 0.016470597 | X10: =Trend_Simulation!E105*Trend_Simulation!N105*4.31 -> -0.0007422444 | Y10: =Trend_Simulation!F105*Trend_Simulation!O105*4.31 -> -0.000771896 | Z10: =Trend_Simulation!G105*Trend_Simulation!P105*4.31 -> 0.0038795069 | AA10: =Trend_Simulation!H105*Trend_Simulation!Q105*4.31 -> -0.018231012 | AB10: =Trend_Simulation!#REF!*Trend_Simulation!#REF!*4.31 -> #REF! | AC10: =SUM(U10:AB10) -> #REF! | AD10: =Summary!I9 -> -0.0023526959 | AE10: =AC10-AD10 -> #REF! | AF10: =LN(1+AD10) -> -0.0023554679 | AH10: 44651 | AI10: 45535
A11: Annualized return | B11: =Summary!V43 -> 0.078300905 | C11: {=PRODUCT(1+Summary!H2:H311)^(12/COUNT(Summary!H2:H311))-1+Summary!Z43} -> 0.055532947 | D11: =Summary!X43 -> 0.17126707 | J11: =Summary!A10 -> 37072 | K11: =K10*(1+Summary!B10) -> 0.81965881 | L11: =L10*(1+Summary!H10) -> 1.0709455 | M11: =M10*(1+Summary!I10) -> 1.3216929 | N11: =MAX($K$3:K11) -> 0.99069493 | O11: =MAX($L$3:L11) -> 1.0786905 | P11: =K11/N11-1 -> -0.17264256 | Q11: =L11/O11-1 -> -0.0071800518 | R11: =M11/MAX($M$3:M11)-1 -> -0.031373901 | T11: =Summary!A10 -> 37072 | U11: =Trend_Simulation!B106*Trend_Simulation!K106*4.31 -> -0.0032096537 | V11: =Trend_Simulation!C106*Trend_Simulation!L106*4.31 -> -0.0082690333 | W11: =Trend_Simulation!D106*Trend_Simulation!M106*4.31 -> 0.0053587996 | X11: =Trend_Simulation!E106*Trend_Simulation!N106*4.31 -> 0.0018264959 | Y11: =Trend_Simulation!F106*Trend_Simulation!O106*4.31 -> 0.0085489447 | Z11: =Trend_Simulation!G106*Trend_Simulation!P106*4.31 -> -0.0023965865 | AA11: =Trend_Simulation!H106*Trend_Simulation!Q106*4.31 -> 0.025746475 | AB11: =Trend_Simulation!#REF!*Trend_Simulation!#REF!*4.31 -> #REF! | AC11: =SUM(U11:AB11) -> #REF! | AD11: =Summary!I10 -> 0.027028994 | AE11: =AC11-AD11 -> #REF! | AF11: =LN(1+AD11) -> 0.026670162 | AH11: 45565 | AI11: 46234
A12: Annualized volatility | B12: =Summary!V44 -> 0.1528659 | C12: =_xlfn.STDEV.S(Summary!H2:H311)*SQRT(12) -> 0.036215307 | D12: =Summary!X44 -> 0.1528286 | J12: =Summary!A11 -> 37103 | K12: =K11*(1+Summary!B11) -> 0.80872905 | L12: =L11*(1+Summary!H11) -> 1.0796573 | M12: =M11*(1+Summary!I11) -> 1.3670648 | N12: =MAX($K$3:K12) -> 0.99069493 | O12: =MAX($L$3:L12) -> 1.0796573 | P12: =K12/N12-1 -> -0.18367499 | Q12: =L12/O12-1 -> 0 | R12: =M12/MAX($M$3:M12)-1 -> 0 | T12: =Summary!A11 -> 37103 | U12: =Trend_Simulation!B107*Trend_Simulation!K107*4.31 -> -0.0070248749 | V12: =Trend_Simulation!C107*Trend_Simulation!L107*4.31 -> 0.0083457508 | W12: =Trend_Simulation!D107*Trend_Simulation!M107*4.31 -> -0.011251136 | X12: =Trend_Simulation!E107*Trend_Simulation!N107*4.31 -> 0.027768059 | Y12: =Trend_Simulation!F107*Trend_Simulation!O107*4.31 -> 0.0040433248 | Z12: =Trend_Simulation!G107*Trend_Simulation!P107*4.31 -> 0.010902859 | AA12: =Trend_Simulation!H107*Trend_Simulation!Q107*4.31 -> 0.0022767497 | AB12: =Trend_Simulation!#REF!*Trend_Simulation!#REF!*4.31 -> #REF! | AC12: =SUM(U12:AB12) -> #REF! | AD12: =Summary!I11 -> 0.034328606 | AE12: =AC12-AD12 -> #REF! | AF12: =LN(1+AD12) -> 0.033752526
A13: Sharpe ratio | B13: =Summary!V45 -> 0.38732378 | C13: =(C11-Summary!Z43)/C12 -> 1.0062221 | D13: =Summary!X45 -> 0.99572181 | J13: =Summary!A12 -> 37134 | K13: =K12*(1+Summary!B12) -> 0.75533565 | L13: =L12*(1+Summary!H12) -> 1.0843356 | M13: =M12*(1+Summary!I12) -> 1.3920626 | N13: =MAX($K$3:K13) -> 0.99069493 | O13: =MAX($L$3:L13) -> 1.0843356 | P13: =K13/N13-1 -> -0.23756988 | Q13: =L13/O13-1 -> 0 | R13: =M13/MAX($M$3:M13)-1 -> 0 | T13: =Summary!A12 -> 37134 | U13: =Trend_Simulation!B108*Trend_Simulation!K108*4.31 -> 0.0096214789 | V13: =Trend_Simulation!C108*Trend_Simulation!L108*4.31 -> -0.013602252 | W13: =Trend_Simulation!D108*Trend_Simulation!M108*4.31 -> 0.00063639722 | X13: =Trend_Simulation!E108*Trend_Simulation!N108*4.31 -> 0.0096037543 | Y13: =Trend_Simulation!F108*Trend_Simulation!O108*4.31 -> 0.020019134 | Z13: =Trend_Simulation!G108*Trend_Simulation!P108*4.31 -> 0.015946253 | AA13: =Trend_Simulation!H108*Trend_Simulation!Q108*4.31 -> -0.023549034 | AB13: =Trend_Simulation!#REF!*Trend_Simulation!#REF!*4.31 -> #REF! | AC13: =SUM(U13:AB13) -> #REF! | AD13: =Summary!I12 -> 0.01828575 | AE13: =AC13-AD13 -> #REF! | AF13: =LN(1+AD13) -> 0.018120577 | AH13: Macro Start | AI13: Macro End
A14: Maximum drawdown | B14: =MIN(P3:P312) -> -0.56071562 | C14: =MIN(Q3:Q312) -> -0.059125533 | D14: =MIN(R3:R312) -> -0.23846854 | J14: =Summary!A13 -> 37164 | K14: =K13*(1+Summary!B13) -> 0.67683332 | L14: =L13*(1+Summary!H13) -> 1.1003826 | M14: =M13*(1+Summary!I13) -> 1.4789991 | N14: =MAX($K$3:K14) -> 0.99069493 | O14: =MAX($L$3:L14) -> 1.1003826 | P14: =K14/N14-1 -> -0.31680954 | Q14: =L14/O14-1 -> 0 | R14: =M14/MAX($M$3:M14)-1 -> 0 | T14: =Summary!A13 -> 37164 | U14: =Trend_Simulation!B109*Trend_Simulation!K109*4.31 -> 0.016875281 | V14: =Trend_Simulation!C109*Trend_Simulation!L109*4.31 -> -0.031745338 | W14: =Trend_Simulation!D109*Trend_Simulation!M109*4.31 -> 6.7011004e-05 | X14: =Trend_Simulation!E109*Trend_Simulation!N109*4.31 -> 0.019818528 | Y14: =Trend_Simulation!F109*Trend_Simulation!O109*4.31 -> 0.031513984 | Z14: =Trend_Simulation!G109*Trend_Simulation!P109*4.31 -> 0.025361343 | AA14: =Trend_Simulation!H109*Trend_Simulation!Q109*4.31 -> 0.0018926587 | AB14: =Trend_Simulation!#REF!*Trend_Simulation!#REF!*4.31 -> #REF! | AC14: =SUM(U14:AB14) -> #REF! | AD14: =Summary!I13 -> 0.062451562 | AE14: =AC14-AD14 -> #REF! | AF14: =LN(1+AD14) -> 0.060579032 | AH14: 36830 | AI14: 38168
A15: Average return in S&P down months | B15: =AVERAGEIF(Summary!B2:B311,"<0",Summary!B2:B311) -> -0.037328582 | C15: =AVERAGEIF(Summary!B2:B311,"<0",Summary!H2:H311) -> 0.0035867751 | D15: =AVERAGEIF(Summary!B2:B311,"<0",Summary!I2:I311) -> 0.015136191 | J15: =Summary!A14 -> 37195 | K15: =K14*(1+Summary!B14) -> 0.68783694 | L15: =L14*(1+Summary!H14) -> 1.106513 | M15: =M14*(1+Summary!I14) -> 1.5137704 | N15: =MAX($K$3:K15) -> 0.99069493 | O15: =MAX($L$3:L15) -> 1.106513 | P15: =K15/N15-1 -> -0.30570257 | Q15: =L15/O15-1 -> 0 | R15: =M15/MAX($M$3:M15)-1 -> 0 | T15: =Summary!A14 -> 37195 | U15: =Trend_Simulation!B110*Trend_Simulation!K110*4.31 -> 0.020043059 | V15: =Trend_Simulation!C110*Trend_Simulation!L110*4.31 -> -0.023030999 | W15: =Trend_Simulation!D110*Trend_Simulation!M110*4.31 -> 0.014004772 | X15: =Trend_Simulation!E110*Trend_Simulation!N110*4.31 -> 0.023256762 | Y15: =Trend_Simulation!F110*Trend_Simulation!O110*4.31 -> -0.0049296327 | Z15: =Trend_Simulation!G110*Trend_Simulation!P110*4.31 -> -0.02021487 | AA15: =Trend_Simulation!H110*Trend_Simulation!Q110*4.31 -> 0.014882328 | AB15: =Trend_Simulation!#REF!*Trend_Simulation!#REF!*4.31 -> #REF! | AC15: =SUM(U15:AB15) -> #REF! | AD15: =Summary!I14 -> 0.02351002 | AE15: =AC15-AD15 -> #REF! | AF15: =LN(1+AD15) -> 0.023237916 | AH15: 38199 | AI15: 39294
A16: Correlation with S&P 500 | B16: 1 | C16: =CORREL(Summary!B2:B311,Summary!H2:H311) -> -0.13407461 | D16: =CORREL(Summary!B2:B311,Summary!I2:I311) -> -0.13407461 | J16: =Summary!A15 -> 37225 | K16: =K15*(1+Summary!B15) -> 0.73923639 | L16: =L15*(1+Summary!H15) -> 1.0887438 | M16: =M15*(1+Summary!I15) -> 1.4111856 | N16: =MAX($K$3:K16) -> 0.99069493 | O16: =MAX($L$3:L16) -> 1.106513 | P16: =K16/N16-1 -> -0.25382035 | Q16: =L16/O16-1 -> -0.016058705 | R16: =M16/MAX($M$3:M16)-1 -> -0.067767735 | T16: =Summary!A15 -> 37225 | U16: =Trend_Simulation!B111*Trend_Simulation!K111*4.31 -> 0.018874282 | V16: =Trend_Simulation!C111*Trend_Simulation!L111*4.31 -> -0.011072253 | W16: =Trend_Simulation!D111*Trend_Simulation!M111*4.31 -> -0.010610761 | X16: =Trend_Simulation!E111*Trend_Simulation!N111*4.31 -> -0.027230969 | Y16: =Trend_Simulation!F111*Trend_Simulation!O111*4.31 -> -0.022658637 | Z16: =Trend_Simulation!G111*Trend_Simulation!P111*4.31 -> -0.020480445 | AA16: =Trend_Simulation!H111*Trend_Simulation!Q111*4.31 -> 0.0039657629 | AB16: =Trend_Simulation!#REF!*Trend_Simulation!#REF!*4.31 -> #REF! | AC16: =SUM(U16:AB16) -> #REF! | AD16: =Summary!I15 -> -0.067767735 | AE16: =AC16-AD16 -> #REF! | AF16: =LN(1+AD16) -> -0.070173284 | AH16: 39325 | AI16: 39813
A17: Average return when S&P ≤ -5% | B17: =AVERAGEIF(Summary!B2:B311,"<=-5%",Summary!B2:B311) -> -0.078545405 | C17: =AVERAGEIF(Summary!B2:B311,"<=-5%",Summary!H2:H311) -> 0.008560294 | D17: =AVERAGEIF(Summary!B2:B311,"<=-5%",Summary!I2:I311) -> 0.036124441 | J17: =Summary!A16 -> 37256 | K17: =K16*(1+Summary!B16) -> 0.74433203 | L17: =L16*(1+Summary!H16) -> 1.0913748 | M17: =M16*(1+Summary!I16) -> 1.4255763 | N17: =MAX($K$3:K17) -> 0.99069493 | O17: =MAX($L$3:L17) -> 1.106513 | P17: =K17/N17-1 -> -0.24867685 | Q17: =L17/O17-1 -> -0.01368102 | R17: =M17/MAX($M$3:M17)-1 -> -0.058261211 | T17: =Summary!A16 -> 37256 | U17: =Trend_Simulation!B112*Trend_Simulation!K112*4.31 -> -0.0016393986 | V17: =Trend_Simulation!C112*Trend_Simulation!L112*4.31 -> -0.00748237 | W17: =Trend_Simulation!D112*Trend_Simulation!M112*4.31 -> 0.0038332286 | X17: =Trend_Simulation!E112*Trend_Simulation!N112*4.31 -> -0.015665356 | Y17: =Trend_Simulation!F112*Trend_Simulation!O112*4.31 -> -0.0020901419 | Z17: =Trend_Simulation!G112*Trend_Simulation!P112*4.31 -> 0.0016155165 | AA17: =Trend_Simulation!H112*Trend_Simulation!Q112*4.31 -> 0.031843598 | AB17: =Trend_Simulation!#REF!*Trend_Simulation!#REF!*4.31 -> #REF! | AC17: =SUM(U17:AB17) -> #REF! | AD17: =Summary!I16 -> 0.010197592 | AE17: =AC17-AD17 -> #REF! | AF17: =LN(1+AD17) -> 0.010145947 | AH17: 39844 | AI17: 42338
J18: =Summary!A17 -> 37287 | K18: =K17*(1+Summary!B17) -> 0.73222066 | L18: =L17*(1+Summary!H17) -> 1.0925357 | M18: =M17*(1+Summary!I17) -> 1.4319755 | N18: =MAX($K$3:K18) -> 0.99069493 | O18: =MAX($L$3:L18) -> 1.106513 | P18: =K18/N18-1 -> -0.26090198 | Q18: =L18/O18-1 -> -0.012631856 | R18: =M18/MAX($M$3:M18)-1 -> -0.054033856 | T18: =Summary!A17 -> 37287 | U18: =Trend_Simulation!B113*Trend_Simulation!K113*4.31 -> 0.010557454 | V18: =Trend_Simulation!C113*Trend_Simulation!L113*4.31 -> -0.0057301256 | W18: =Trend_Simulation!D113*Trend_Simulation!M113*4.31 -> -0.02508208 | X18: =Trend_Simulation!E113*Trend_Simulation!N113*4.31 -> 0.0064564947 | Y18: =Trend_Simulation!F113*Trend_Simulation!O113*4.31 -> 0.0049338639 | Z18: =Trend_Simulation!G113*Trend_Simulation!P113*4.31 -> 0.0023195492 | AA18: =Trend_Simulation!H113*Trend_Simulation!Q113*4.31 -> 0.011129461 | AB18: =Trend_Simulation!#REF!*Trend_Simulation!#REF!*4.31 -> #REF! | AC18: =SUM(U18:AB18) -> #REF! | AD18: =Summary!I17 -> 0.0044888826 | AE18: =AC18-AD18 -> #REF! | AF18: =LN(1+AD18) -> 0.0044788376 | AH18: 42369 | AI18: 43677
A19: THREE MOST IMPORTANT TAKEAWAYS | J19: =Summary!A18 -> 37315 | K19: =K18*(1+Summary!B18) -> 0.71700761 | L19: =L18*(1+Summary!H18) -> 1.1075646 | M19: =M18*(1+Summary!I18) -> 1.5151023 | N19: =MAX($K$3:K19) -> 0.99069493 | O19: =MAX($L$3:L19) -> 1.1075646 | P19: =K19/N19-1 -> -0.27625792 | Q19: =L19/O19-1 -> 0 | R19: =M19/MAX($M$3:M19)-1 -> 0 | T19: =Summary!A18 -> 37315 | U19: =Trend_Simulation!B114*Trend_Simulation!K114*4.31 -> -0.0094167297 | V19: =Trend_Simulation!C114*Trend_Simulation!L114*4.31 -> 0.025175663 | W19: =Trend_Simulation!D114*Trend_Simulation!M114*4.31 -> 0.0091327202 | X19: =Trend_Simulation!E114*Trend_Simulation!N114*4.31 -> 0.011973119 | Y19: =Trend_Simulation!F114*Trend_Simulation!O114*4.31 -> 0.0062999234 | Z19: =Trend_Simulation!G114*Trend_Simulation!P114*4.31 -> 0.015210764 | AA19: =Trend_Simulation!H114*Trend_Simulation!Q114*4.31 -> 0.00091301979 | AB19: =Trend_Simulation!#REF!*Trend_Simulation!#REF!*4.31 -> #REF! | AC19: =SUM(U19:AB19) -> #REF! | AD19: =Summary!I18 -> 0.058050437 | AE19: =AC19-AD19 -> #REF! | AF19: =LN(1+AD19) -> 0.056428005 | AH19: 43708 | AI19: 44620
A20: ="1 | Diversification — Trend correlation to the S&P 500 was "&TEXT(C16,"0.00")&" both before and after leverage, providing a distinct return stream rather than amplified equity beta." -> 1 | Diversification — Trend correlation to the S&P 500 was -0.13 both before and after leverage, providing a distinct return stream rather than amplified equity beta. | J20: =Summary!A19 -> 37346 | K20: =K19*(1+Summary!B19) -> 0.74263348 | L20: =L19*(1+Summary!H19) -> 1.0945598 | M20: =M19*(1+Summary!I19) -> 1.4400284 | N20: =MAX($K$3:K20) -> 0.99069493 | O20: =MAX($L$3:L20) -> 1.1075646 | P20: =K20/N20-1 -> -0.25039135 | Q20: =L20/O20-1 -> -0.011741799 | R20: =M20/MAX($M$3:M20)-1 -> -0.04955039 | T20: =Summary!A19 -> 37346 | U20: =Trend_Simulation!B115*Trend_Simulation!K115*4.31 -> -0.029101787 | V20: =Trend_Simulation!C115*Trend_Simulation!L115*4.31 -> 0.0094977996 | W20: =Trend_Simulation!D115*Trend_Simulation!M115*4.31 -> 0.022613607 | X20: =Trend_Simulation!E115*Trend_Simulation!N115*4.31 -> -0.030288986 | Y20: =Trend_Simulation!F115*Trend_Simulation!O115*4.31 -> -0.010837166 | Z20: =Trend_Simulation!G115*Trend_Simulation!P115*4.31 -> -0.0082317784 | AA20: =Trend_Simulation!H115*Trend_Simulation!Q115*4.31 -> -0.0042588408 | AB20: =Trend_Simulation!#REF!*Trend_Simulation!#REF!*4.31 -> #REF! | AC20: =SUM(U20:AB20) -> #REF! | AD20: =Summary!I19 -> -0.04955039 | AE20: =AC20-AD20 -> #REF! | AF20: =LN(1+AD20) -> -0.050820133 | AH20: 44651 | AI20: 45535
J21: =Summary!A20 -> 37376 | K21: =K20*(1+Summary!B20) -> 0.69610812 | L21: =L20*(1+Summary!H20) -> 1.1096323 | M21: =M20*(1+Summary!I20) -> 1.5237096 | N21: =MAX($K$3:K21) -> 0.99069493 | O21: =MAX($L$3:L21) -> 1.1096323 | P21: =K21/N21-1 -> -0.29735371 | Q21: =L21/O21-1 -> 0 | R21: =M21/MAX($M$3:M21)-1 -> 0 | T21: =Summary!A20 -> 37376 | U21: =Trend_Simulation!B116*Trend_Simulation!K116*4.31 -> -0.0047800081 | V21: =Trend_Simulation!C116*Trend_Simulation!L116*4.31 -> 0.0090848615 | W21: =Trend_Simulation!D116*Trend_Simulation!M116*4.31 -> 0.0086333022 | X21: =Trend_Simulation!E116*Trend_Simulation!N116*4.31 -> 0.028069913 | Y21: =Trend_Simulation!F116*Trend_Simulation!O116*4.31 -> 0.018996608 | Z21: =Trend_Simulation!G116*Trend_Simulation!P116*4.31 -> 0.01505794 | AA21: =Trend_Simulation!H116*Trend_Simulation!Q116*4.31 -> -0.015712503 | AB21: =Trend_Simulation!#REF!*Trend_Simulation!#REF!*4.31 -> #REF! | AC21: =SUM(U21:AB21) -> #REF! | AD21: =Summary!I20 -> 0.058110783 | AE21: =AC21-AD21 -> #REF! | AF21: =LN(1+AD21) -> 0.056485038 | AH21: 45565 | AI21: 46234
A22: ="2 | Crisis resilience — In 118 negative S&P months, leveraged trend averaged "&TEXT(D15,"0.0%")&" versus "&TEXT(B15,"0.0%")&" for equities; in the 37 months with S&P losses of at least 5%, it averaged "&TEXT(D17,"0.0%")&"." -> 2 | Crisis resilience — In 118 negative S&P months, leveraged trend averaged 1.5% versus -3.7% for equities; in the 37 months with S&P losses of at least 5%, it averaged 3.6%. | J22: =Summary!A21 -> 37407 | K22: =K21*(1+Summary!B21) -> 0.68983088 | L22: =L21*(1+Summary!H21) -> 1.1221627 | M22: =M21*(1+Summary!I21) -> 1.5963204 | N22: =MAX($K$3:K22) -> 0.99069493 | O22: =MAX($L$3:L22) -> 1.1221627 | P22: =K22/N22-1 -> -0.3036899 | Q22: =L22/O22-1 -> 0 | R22: =M22/MAX($M$3:M22)-1 -> 0 | T22: =Summary!A21 -> 37407 | U22: =Trend_Simulation!B117*Trend_Simulation!K117*4.31 -> 0.01342671 | V22: =Trend_Simulation!C117*Trend_Simulation!L117*4.31 -> 0.027947052 | W22: =Trend_Simulation!D117*Trend_Simulation!M117*4.31 -> 0.004872507 | X22: =Trend_Simulation!E117*Trend_Simulation!N117*4.31 -> 0.0098306496 | Y22: =Trend_Simulation!F117*Trend_Simulation!O117*4.31 -> 0.0027343384 | Z22: =Trend_Simulation!G117*Trend_Simulation!P117*4.31 -> 0.0067435773 | AA22: =Trend_Simulation!H117*Trend_Simulation!Q117*4.31 -> -0.016884504 | AB22: =Trend_Simulation!#REF!*Trend_Simulation!#REF!*4.31 -> #REF! | AC22: =SUM(U22:AB22) -> #REF! | AD22: =Summary!I21 -> 0.047654013 | AE22: =AC22-AD22 -> #REF! | AF22: =LN(1+AD22) -> 0.046553391
J23: =Summary!A22 -> 37437 | K23: =K22*(1+Summary!B22) -> 0.63909608 | L23: =L22*(1+Summary!H22) -> 1.1285714 | M23: =M22*(1+Summary!I22) -> 1.6347927 | N23: =MAX($K$3:K23) -> 0.99069493 | O23: =MAX($L$3:L23) -> 1.1285714 | P23: =K23/N23-1 -> -0.35490123 | Q23: =L23/O23-1 -> 0 | R23: =M23/MAX($M$3:M23)-1 -> 0 | T23: =Summary!A22 -> 37437 | U23: =Trend_Simulation!B118*Trend_Simulation!K118*4.31 -> -0.0073982915 | V23: =Trend_Simulation!C118*Trend_Simulation!L118*4.31 -> -0.020829354 | W23: =Trend_Simulation!D118*Trend_Simulation!M118*4.31 -> 0.014611839 | X23: =Trend_Simulation!E118*Trend_Simulation!N118*4.31 -> 0.017152104 | Y23: =Trend_Simulation!F118*Trend_Simulation!O118*4.31 -> 0.022300989 | Z23: =Trend_Simulation!G118*Trend_Simulation!P118*4.31 -> 0.016205742 | AA23: =Trend_Simulation!H118*Trend_Simulation!Q118*4.31 -> -0.017428477 | AB23: =Trend_Simulation!#REF!*Trend_Simulation!#REF!*4.31 -> #REF! | AC23: =SUM(U23:AB23) -> #REF! | AD23: =Summary!I22 -> 0.024100559 | AE23: =AC23-AD23 -> #REF! | AF23: =LN(1+AD23) -> 0.023814724
A24: ="3 | Leverage efficiency — Levered trend achieved "&TEXT(D11,"0.0%")&" annualized at "&TEXT(D12,"0.0%")&" volatility versus "&TEXT(B11,"0.0%")&" and "&TEXT(B12,"0.0%")&" for the S&P 500, though the "&TEXT(D14,"0.0%")&" drawdown shows leverage remains consequential." -> 3 | Leverage efficiency — Levered trend achieved 17.1% annualized at 15.3% volatility versus 7.8% and 15.3% for the S&P 500, though the -23.8% drawdown shows leverage remains consequential. | J24: =Summary!A23 -> 37468 | K24: =K23*(1+Summary!B23) -> 0.58843512 | L24: =L23*(1+Summary!H23) -> 1.1405618 | M24: =M23*(1+Summary!I23) -> 1.7080885 | N24: =MAX($K$3:K24) -> 0.99069493 | O24: =MAX($L$3:L24) -> 1.1405618 | P24: =K24/N24-1 -> -0.40603802 | Q24: =L24/O24-1 -> 0 | R24: =M24/MAX($M$3:M24)-1 -> 0 | T24: =Summary!A23 -> 37468 | U24: =Trend_Simulation!B119*Trend_Simulation!K119*4.31 -> -0.0038052811 | V24: =Trend_Simulation!C119*Trend_Simulation!L119*4.31 -> -0.017278239 | W24: =Trend_Simulation!D119*Trend_Simulation!M119*4.31 -> 0.0037075481 | X24: =Trend_Simulation!E119*Trend_Simulation!N119*4.31 -> 0.029099034 | Y24: =Trend_Simulation!F119*Trend_Simulation!O119*4.31 -> 0.024036321 | Z24: =Trend_Simulation!G119*Trend_Simulation!P119*4.31 -> 0.010396315 | AA24: =Trend_Simulation!H119*Trend_Simulation!Q119*4.31 -> -0.00036458564 | AB24: =Trend_Simulation!#REF!*Trend_Simulation!#REF!*4.31 -> #REF! | AC24: =SUM(U24:AB24) -> #REF! | AD24: =Summary!I23 -> 0.044834917 | AE24: =AC24-AD24 -> #REF! | AF24: =LN(1+AD24) -> 0.043858899
J25: =Summary!A24 -> 37499 | K25: =K24*(1+Summary!B24) -> 0.59131526 | L25: =L24*(1+Summary!H24) -> 1.1543449 | M25: =M24*(1+Summary!I24) -> 1.795195 | N25: =MAX($K$3:K25) -> 0.99069493 | O25: =MAX($L$3:L25) -> 1.1543449 | P25: =K25/N25-1 -> -0.40313082 | Q25: =L25/O25-1 -> 0 | R25: =M25/MAX($M$3:M25)-1 -> 0 | T25: =Summary!A24 -> 37499 | U25: =Trend_Simulation!B120*Trend_Simulation!K120*4.31 -> -0.013947473 | V25: =Trend_Simulation!C120*Trend_Simulation!L120*4.31 -> 0.014297668 | W25: =Trend_Simulation!D120*Trend_Simulation!M120*4.31 -> 0.024876495 | X25: =Trend_Simulation!E120*Trend_Simulation!N120*4.31 -> 0.021313554 | Y25: =Trend_Simulation!F120*Trend_Simulation!O120*4.31 -> -0.001484144 | Z25: =Trend_Simulation!G120*Trend_Simulation!P120*4.31 -> 0.0026660022 | AA25: =Trend_Simulation!H120*Trend_Simulation!Q120*4.31 -> 0.0043619871 | AB25: =Trend_Simulation!#REF!*Trend_Simulation!#REF!*4.31 -> #REF! | AC25: =SUM(U25:AB25) -> #REF! | AD25: =Summary!I24 -> 0.050996486 | AE25: =AC25-AD25 -> #REF! | AF25: =LN(1+AD25) -> 0.049738749
J26: =Summary!A25 -> 37529 | K26: =K25*(1+Summary!B25) -> 0.5259582 | L26: =L25*(1+Summary!H25) -> 1.182254 | M26: =M25*(1+Summary!I25) -> 1.9783567 | N26: =MAX($K$3:K26) -> 0.99069493 | O26: =MAX($L$3:L26) -> 1.182254 | P26: =K26/N26-1 -> -0.46910175 | Q26: =L26/O26-1 -> 0 | R26: =M26/MAX($M$3:M26)-1 -> 0 | T26: =Summary!A25 -> 37529 | U26: =Trend_Simulation!B121*Trend_Simulation!K121*4.31 -> -0.0083317943 | V26: =Trend_Simulation!C121*Trend_Simulation!L121*4.31 -> 0.01805692 | W26: =Trend_Simulation!D121*Trend_Simulation!M121*4.31 -> -0.0017745947 | X26: =Trend_Simulation!E121*Trend_Simulation!N121*4.31 -> 0.034140699 | Y26: =Trend_Simulation!F121*Trend_Simulation!O121*4.31 -> 0.033514613 | Z26: =Trend_Simulation!G121*Trend_Simulation!P121*4.31 -> 0.014489321 | AA26: =Trend_Simulation!H121*Trend_Simulation!Q121*4.31 -> 0.014109693 | AB26: =Trend_Simulation!#REF!*Trend_Simulation!#REF!*4.31 -> #REF! | AC26: =SUM(U26:AB26) -> #REF! | AD26: =Summary!I25 -> 0.10202889 | AE26: =AC26-AD26 -> #REF! | AF26: =LN(1+AD26) -> 0.097152923
J27: =Summary!A26 -> 37560 | K27: =K26*(1+Summary!B26) -> 0.57144967 | L27: =L26*(1+Summary!H26) -> 1.1655109 | M27: =M26*(1+Summary!I26) -> 1.860123 | N27: =MAX($K$3:K27) -> 0.99069493 | O27: =MAX($L$3:L27) -> 1.182254 | P27: =K27/N27-1 -> -0.423183 | Q27: =L27/O27-1 -> -0.014161995 | R27: =M27/MAX($M$3:M27)-1 -> -0.059763618 | T27: =Summary!A26 -> 37560 | U27: =Trend_Simulation!B122*Trend_Simulation!K122*4.31 -> -0.016097052 | V27: =Trend_Simulation!C122*Trend_Simulation!L122*4.31 -> -0.010488745 | W27: =Trend_Simulation!D122*Trend_Simulation!M122*4.31 -> 0.020009061 | X27: =Trend_Simulation!E122*Trend_Simulation!N122*4.31 -> -0.0094786306 | Y27: =Trend_Simulation!F122*Trend_Simulation!O122*4.31 -> -0.02622645 | Z27: =Trend_Simulation!G122*Trend_Simulation!P122*4.31 -> -0.022860493 | AA27: =Trend_Simulation!H122*Trend_Simulation!Q122*4.31 -> 0.0041041126 | AB27: =Trend_Simulation!#REF!*Trend_Simulation!#REF!*4.31 -> #REF! | AC27: =SUM(U27:AB27) -> #REF! | AD27: =Summary!I26 -> -0.059763618 | AE27: =AC27-AD27 -> #REF! | AF27: =LN(1+AD27) -> -0.061623965
J28: =Summary!A27 -> 37590 | K28: =K27*(1+Summary!B27) -> 0.60409128 | L28: =L27*(1+Summary!H27) -> 1.1528398 | M28: =M27*(1+Summary!I27) -> 1.774783 | N28: =MAX($K$3:K28) -> 0.99069493 | O28: =MAX($L$3:L28) -> 1.182254 | P28: =K28/N28-1 -> -0.39023481 | Q28: =L28/O28-1 -> -0.024879755 | R28: =M28/MAX($M$3:M28)-1 -> -0.10290042 | T28: =Summary!A27 -> 37590 | U28: =Trend_Simulation!B123*Trend_Simulation!K123*4.31 -> -0.00028979162 | V28: =Trend_Simulation!C123*Trend_Simulation!L123*4.31 -> -0.0020588819 | W28: =Trend_Simulation!D123*Trend_Simulation!M123*4.31 -> 0.0023121973 | X28: =Trend_Simulation!E123*Trend_Simulation!N123*4.31 -> -0.017082877 | Y28: =Trend_Simulation!F123*Trend_Simulation!O123*4.31 -> -0.016019826 | Z28: =Trend_Simulation!G123*Trend_Simulation!P123*4.31 -> -0.014300255 | AA28: =Trend_Simulation!H123*Trend_Simulation!Q123*4.31 -> 0.00058229855 | AB28: =Trend_Simulation!#REF!*Trend_Simulation!#REF!*4.31 -> #REF! | AC28: =SUM(U28:AB28) -> #REF! | AD28: =Summary!I27 -> -0.045878681 | AE28: =AC28-AD28 -> #REF! | AF28: =LN(1+AD28) -> -0.046964446
J29: =Summary!A28 -> 37621 | K29: =K28*(1+Summary!B28) -> 0.56790488 | L29: =L28*(1+Summary!H28) -> 1.1840878 | M29: =M28*(1+Summary!I28) -> 1.97779 | N29: =MAX($K$3:K29) -> 0.99069493 | O29: =MAX($L$3:L29) -> 1.1840878 | P29: =K29/N29-1 -> -0.42676109 | Q29: =L29/O29-1 -> 0 | R29: =M29/MAX($M$3:M29)-1 -> -0.00028643417 | T29: =Summary!A28 -> 37621 | U29: =Trend_Simulation!B124*Trend_Simulation!K124*4.31 -> 0.020859197 | V29: =Trend_Simulation!C124*Trend_Simulation!L124*4.31 -> 0.04573934 | W29: =Trend_Simulation!D124*Trend_Simulation!M124*4.31 -> 0.0054905997 | X29: =Trend_Simulation!E124*Trend_Simulation!N124*4.31 -> 0.030033525 | Y29: =Trend_Simulation!F124*Trend_Simulation!O124*4.31 -> 0.016475919 | Z29: =Trend_Simulation!G124*Trend_Simulation!P124*4.31 -> 0.013465593 | AA29: =Trend_Simulation!H124*Trend_Simulation!Q124*4.31 -> -0.015240534 | AB29: =Trend_Simulation!#REF!*Trend_Simulation!#REF!*4.31 -> #REF! | AC29: =SUM(U29:AB29) -> #REF! | AD29: =Summary!I28 -> 0.11438417 | AE29: =AC29-AD29 -> #REF! | AF29: =LN(1+AD29) -> 0.10830194
J30: =Summary!A29 -> 37652 | K30: =K29*(1+Summary!B29) -> 0.55224873 | L30: =L29*(1+Summary!H29) -> 1.1965232 | M30: =M29*(1+Summary!I29) -> 2.0654431 | N30: =MAX($K$3:K30) -> 0.99069493 | O30: =MAX($L$3:L30) -> 1.1965232 | P30: =K30/N30-1 -> -0.44256429 | Q30: =L30/O30-1 -> 0 | R30: =M30/MAX($M$3:M30)-1 -> 0 | T30: =Summary!A29 -> 37652 | U30: =Trend_Simulation!B125*Trend_Simulation!K125*4.31 -> 0.016365232 | V30: =Trend_Simulation!C125*Trend_Simulation!L125*4.31 -> 0.024159898 | W30: =Trend_Simulation!D125*Trend_Simulation!M125*4.31 -> 0.010491538 | X30: =Trend_Simulation!E125*Trend_Simulation!N125*4.31 -> -0.0080606406 | Y30: =Trend_Simulation!F125*Trend_Simulation!O125*4.31 -> 0.0075428045 | Z30: =Trend_Simulation!G125*Trend_Simulation!P125*4.31 -> 0.00029685265 | AA30: =Trend_Simulation!H125*Trend_Simulation!Q125*4.31 -> -0.0055318006 | AB30: =Trend_Simulation!#REF!*Trend_Simulation!#REF!*4.31 -> #REF! | AC30: =SUM(U30:AB30) -> #REF! | AD30: =Summary!I29 -> 0.044318699 | AE30: =AC30-AD30 -> #REF! | AF30: =LN(1+AD30) -> 0.04336471
J31: =Summary!A30 -> 37680 | K31: =K30*(1+Summary!B30) -> 0.54338675 | L31: =L30*(1+Summary!H30) -> 1.2081927 | M31: =M30*(1+Summary!I30) -> 2.1504503 | N31: =MAX($K$3:K31) -> 0.99069493 | O31: =MAX($L$3:L31) -> 1.2081927 | P31: =K31/N31-1 -> -0.4515095 | Q31: =L31/O31-1 -> 0 | R31: =M31/MAX($M$3:M31)-1 -> 0 | T31: =Summary!A30 -> 37680 | U31: =Trend_Simulation!B126*Trend_Simulation!K126*4.31 -> 0.028748028 | V31: =Trend_Simulation!C126*Trend_Simulation!L126*4.31 -> -0.020899992 | W31: =Trend_Simulation!D126*Trend_Simulation!M126*4.31 -> 0.0058584902 | X31: =Trend_Simulation!E126*Trend_Simulation!N126*4.31 -> 0.020444732 | Y31: =Trend_Simulation!F126*Trend_Simulation!O126*4.31 -> 0.0044184796 | Z31: =Trend_Simulation!G126*Trend_Simulation!P126*4.31 -> -0.00309028 | AA31: =Trend_Simulation!H126*Trend_Simulation!Q126*4.31 -> 0.0065551808 | AB31: =Trend_Simulation!#REF!*Trend_Simulation!#REF!*4.31 -> #REF! | AC31: =SUM(U31:AB31) -> #REF! | AD31: =Summary!I30 -> 0.041156884 | AE31: =AC31-AD31 -> #REF! | AF31: =LN(1+AD31) -> 0.040332484
J32: =Summary!A31 -> 37711 | K32: =K31*(1+Summary!B31) -> 0.54803929 | L32: =L31*(1+Summary!H31) -> 1.1959274 | M32: =M31*(1+Summary!I31) -> 2.0583243 | N32: =MAX($K$3:K32) -> 0.99069493 | O32: =MAX($L$3:L32) -> 1.2081927 | P32: =K32/N32-1 -> -0.44681327 | Q32: =L32/O32-1 -> -0.010151735 | R32: =M32/MAX($M$3:M32)-1 -> -0.04284032 | T32: =Summary!A31 -> 37711 | U32: =Trend_Simulation!B127*Trend_Simulation!K127*4.31 -> -0.026131079 | V32: =Trend_Simulation!C127*Trend_Simulation!L127*4.31 -> -0.015824953 | W32: =Trend_Simulation!D127*Trend_Simulation!M127*4.31 -> 0.0068016183 | X32: =Trend_Simulation!E127*Trend_Simulation!N127*4.31 -> -0.0034532392 | Y32: =Trend_Simulation!F127*Trend_Simulation!O127*4.31 -> -0.002301669 | Z32: =Trend_Simulation!G127*Trend_Simulation!P127*4.31 -> -0.00093732532 | AA32: =Trend_Simulation!H127*Trend_Simulation!Q127*4.31 -> -0.0019073293 | AB32: =Trend_Simulation!#REF!*Trend_Simulation!#REF!*4.31 -> #REF! | AC32: =SUM(U32:AB32) -> #REF! | AD32: =Summary!I31 -> -0.04284032 | AE32: =AC32-AD32 -> #REF! | AF32: =LN(1+AD32) -> -0.043785047
J33: =Summary!A32 -> 37741 | K33: =K32*(1+Summary!B32) -> 0.59271841 | L33: =L32*(1+Summary!H32) -> 1.1854558 | M33: =M32*(1+Summary!I32) -> 1.982268 | N33: =MAX($K$3:K33) -> 0.99069493 | O33: =MAX($L$3:L33) -> 1.2081927 | P33: =K33/N33-1 -> -0.4017145 | Q33: =L33/O33-1 -> -0.01881891 | R33: =M33/MAX($M$3:M33)-1 -> -0.078207937 | T33: =Summary!A32 -> 37741 | U33: =Trend_Simulation!B128*Trend_Simulation!K128*4.31 -> -0.013933046 | V33: =Trend_Simulation!C128*Trend_Simulation!L128*4.31 -> 0.0028883683 | W33: =Trend_Simulation!D128*Trend_Simulation!M128*4.31 -> 0.0078485975 | X33: =Trend_Simulation!E128*Trend_Simulation!N128*4.31 -> 0.0017285846 | Y33: =Trend_Simulation!F128*Trend_Simulation!O128*4.31 -> -0.022793284 | Z33: =Trend_Simulation!G128*Trend_Simulation!P128*4.31 -> -0.010013281 | AA33: =Trend_Simulation!H128*Trend_Simulation!Q128*4.31 -> -0.0034645761 | AB33: =Trend_Simulation!#REF!*Trend_Simulation!#REF!*4.31 -> #REF! | AC33: =SUM(U33:AB33) -> #REF! | AD33: =Summary!I32 -> -0.036950592 | AE33: =AC33-AD33 -> #REF! | AF33: =LN(1+AD33) -> -0.037650562
J34: =Summary!A33 -> 37772 | K34: =K33*(1+Summary!B33) -> 0.62329222 | L34: =L33*(1+Summary!H33) -> 1.2013054 | M34: =M33*(1+Summary!I33) -> 2.0941105 | N34: =MAX($K$3:K34) -> 0.99069493 | O34: =MAX($L$3:L34) -> 1.2081927 | P34: =K34/N34-1 -> -0.37085352 | Q34: =L34/O34-1 -> -0.0057005031 | R34: =M34/MAX($M$3:M34)-1 -> -0.026199077 | T34: =Summary!A33 -> 37772 | U34: =Trend_Simulation!B129*Trend_Simulation!K129*4.31 -> 0.0096437396 | V34: =Trend_Simulation!C129*Trend_Simulation!L129*4.31 -> 0.029094941 | W34: =Trend_Simulation!D129*Trend_Simulation!M129*4.31 -> 0.01730106 | X34: =Trend_Simulation!E129*Trend_Simulation!N129*4.31 -> 0.02700729 | Y34: =Trend_Simulation!F129*Trend_Simulation!O129*4.31 -> -0.013679889 | Z34: =Trend_Simulation!G129*Trend_Simulation!P129*4.31 -> -0.0095789036 | AA34: =Trend_Simulation!H129*Trend_Simulation!Q129*4.31 -> -0.0021634694 | AB34: =Trend_Simulation!#REF!*Trend_Simulation!#REF!*4.31 -> #REF! | AC34: =SUM(U34:AB34) -> #REF! | AD34: =Summary!I33 -> 0.056421467 | AE34: =AC34-AD34 -> #REF! | AF34: =LN(1+AD34) -> 0.054887222
J35: =Summary!A34 -> 37802 | K35: =K34*(1+Summary!B34) -> 0.6305295 | L35: =L34*(1+Summary!H34) -> 1.1828222 | M35: =M34*(1+Summary!I34) -> 1.9581431 | N35: =MAX($K$3:K35) -> 0.99069493 | O35: =MAX($L$3:L35) -> 1.2081927 | P35: =K35/N35-1 -> -0.36354827 | Q35: =L35/O35-1 -> -0.020998691 | R35: =M35/MAX($M$3:M35)-1 -> -0.089426488 | T35: =Summary!A34 -> 37802 | U35: =Trend_Simulation!B130*Trend_Simulation!K130*4.31 -> 0.0090504253 | V35: =Trend_Simulation!C130*Trend_Simulation!L130*4.31 -> -0.019747169 | W35: =Trend_Simulation!D130*Trend_Simulation!M130*4.31 -> -0.043109554 | X35: =Trend_Simulation!E130*Trend_Simulation!N130*4.31 -> -0.0066212279 | Y35: =Trend_Simulation!F130*Trend_Simulation!O130*4.31 -> -0.0030389715 | Z35: =Trend_Simulation!G130*Trend_Simulation!P130*4.31 -> -0.00025088811 | AA35: =Trend_Simulation!H130*Trend_Simulation!Q130*4.31 -> -0.0025958228 | AB35: =Trend_Simulation!#REF!*Trend_Simulation!#REF!*4.31 -> #REF! | AC35: =SUM(U35:AB35) -> #REF! | AD35: =Summary!I34 -> -0.064928477 | AE35: =AC35-AD35 -> #REF! | AF35: =LN(1+AD35) -> -0.067132258
J36: =Summary!A35 -> 37833 | K36: =K35*(1+Summary!B35) -> 0.64094232 | L36: =L35*(1+Summary!H35) -> 1.1760406 | M36: =M35*(1+Summary!I35) -> 1.9107655 | N36: =MAX($K$3:K36) -> 0.99069493 | O36: =MAX($L$3:L36) -> 1.2081927 | P36: =K36/N36-1 -> -0.35303764 | Q36: =L36/O36-1 -> -0.026611748 | R36: =M36/MAX($M$3:M36)-1 -> -0.11145797 | T36: =Summary!A35 -> 37833 | U36: =Trend_Simulation!B131*Trend_Simulation!K131*4.31 -> 0.0042465014 | V36: =Trend_Simulation!C131*Trend_Simulation!L131*4.31 -> 0.0091956005 | W36: =Trend_Simulation!D131*Trend_Simulation!M131*4.31 -> 0.0039843162 | X36: =Trend_Simulation!E131*Trend_Simulation!N131*4.31 -> -0.048336642 | Y36: =Trend_Simulation!F131*Trend_Simulation!O131*4.31 -> -0.0046342077 | Z36: =Trend_Simulation!G131*Trend_Simulation!P131*4.31 -> 0.0079369536 | AA36: =Trend_Simulation!H131*Trend_Simulation!Q131*4.31 -> 0.0028963002 | AB36: =Trend_Simulation!#REF!*Trend_Simulation!#REF!*4.31 -> #REF! | AC36: =SUM(U36:AB36) -> #REF! | AD36: =Summary!I35 -> -0.024195167 | AE36: =AC36-AD36 -> #REF! | AF36: =LN(1+AD36) -> -0.024492678
J37: =Summary!A36 -> 37864 | K37: =K36*(1+Summary!B36) -> 0.65290599 | L37: =L36*(1+Summary!H36) -> 1.1669646 | M37: =M36*(1+Summary!I36) -> 1.848537 | N37: =MAX($K$3:K37) -> 0.99069493 | O37: =MAX($L$3:L37) -> 1.2081927 | P37: =K37/N37-1 -> -0.34096161 | Q37: =L37/O37-1 -> -0.034123746 | R37: =M37/MAX($M$3:M37)-1 -> -0.14039539 | T37: =Summary!A36 -> 37864 | U37: =Trend_Simulation!B132*Trend_Simulation!K132*4.31 -> 0.0061953773 | V37: =Trend_Simulation!C132*Trend_Simulation!L132*4.31 -> 0.024670589 | W37: =Trend_Simulation!D132*Trend_Simulation!M132*4.31 -> -0.062514743 | X37: =Trend_Simulation!E132*Trend_Simulation!N132*4.31 -> 0.0060391165 | Y37: =Trend_Simulation!F132*Trend_Simulation!O132*4.31 -> 0.0053255042 | Z37: =Trend_Simulation!G132*Trend_Simulation!P132*4.31 -> 0.0064053215 | AA37: =Trend_Simulation!H132*Trend_Simulation!Q132*4.31 -> -0.019383035 | AB37: =Trend_Simulation!#REF!*Trend_Simulation!#REF!*4.31 -> #REF! | AC37: =SUM(U37:AB37) -> #REF! | AD37: =Summary!I36 -> -0.032567306 | AE37: =AC37-AD37 -> #REF! | AF37: =LN(1+AD37) -> -0.033109423
A38: DATA QUALITY AND INTERPRETATION | J38: =Summary!A37 -> 37894 | K38: =K37*(1+Summary!B37) -> 0.64493021 | L38: =L37*(1+Summary!H37) -> 1.1778524 | M38: =M37*(1+Summary!I37) -> 1.9213188 | N38: =MAX($K$3:K38) -> 0.99069493 | O38: =MAX($L$3:L38) -> 1.2081927 | P38: =K38/N38-1 -> -0.3490123 | Q38: =L38/O38-1 -> -0.025112117 | R38: =M38/MAX($M$3:M38)-1 -> -0.1065505 | T38: =Summary!A37 -> 37894 | U38: =Trend_Simulation!B133*Trend_Simulation!K133*4.31 -> -0.014009157 | V38: =Trend_Simulation!C133*Trend_Simulation!L133*4.31 -> 0.010819096 | W38: =Trend_Simulation!D133*Trend_Simulation!M133*4.31 -> -0.011717732 | X38: =Trend_Simulation!E133*Trend_Simulation!N133*4.31 -> 0.035253708 | Y38: =Trend_Simulation!F133*Trend_Simulation!O133*4.31 -> -0.0038230448 | Z38: =Trend_Simulation!G133*Trend_Simulation!P133*4.31 -> -0.0040834721 | AA38: =Trend_Simulation!H133*Trend_Simulation!Q133*4.31 -> 0.027772918 | AB38: =Trend_Simulation!#REF!*Trend_Simulation!#REF!*4.31 -> #REF! | AC38: =SUM(U38:AB38) -> #REF! | AD38: =Summary!I37 -> 0.039372616 | AE38: =AC38-AD38 -> #REF! | AF38: =LN(1+AD38) -> 0.038617278
A39: All 310 observations in Summary!B2:B311, Summary!H2:H311, and Summary!I2:I311 are numeric and complete. The existing #VALUE! in Summary!J2 is an unrelated percentile formula and is excluded. Trend Levered Return uses approximately 4.31x exposure; the workbook does not visibly deduct financing costs, trading costs, slippage, or capacity effects, so reported leveraged results are best treated as gross backtest outcomes. | J39: =Summary!A38 -> 37925 | K39: =K38*(1+Summary!B38) -> 0.68096891 | L39: =L38*(1+Summary!H38) -> 1.1861633 | M39: =M38*(1+Summary!I38) -> 1.9785281 | N39: =MAX($K$3:K39) -> 0.99069493 | O39: =MAX($L$3:L39) -> 1.2081927 | P39: =K39/N39-1 -> -0.31263511 | Q39: =L39/O39-1 -> -0.018233368 | R39: =M39/MAX($M$3:M39)-1 -> -0.079947096 | T39: =Summary!A38 -> 37925 | U39: =Trend_Simulation!B134*Trend_Simulation!K134*4.31 -> 0.0076110319 | V39: =Trend_Simulation!C134*Trend_Simulation!L134*4.31 -> -0.0017276573 | W39: =Trend_Simulation!D134*Trend_Simulation!M134*4.31 -> 0.00026690278 | X39: =Trend_Simulation!E134*Trend_Simulation!N134*4.31 -> -0.015511313 | Y39: =Trend_Simulation!F134*Trend_Simulation!O134*4.31 -> 0.017870381 | Z39: =Trend_Simulation!G134*Trend_Simulation!P134*4.31 -> 0.012515345 | AA39: =Trend_Simulation!H134*Trend_Simulation!Q134*4.31 -> 0.0093864051 | AB39: =Trend_Simulation!#REF!*Trend_Simulation!#REF!*4.31 -> #REF! | AC39: =SUM(U39:AB39) -> #REF! | AD39: =Summary!I38 -> 0.029776062 | AE39: =AC39-AD39 -> #REF! | AF39: =LN(1+AD39) -> 0.029341363
J40: =Summary!A39 -> 37955 | K40: =K39*(1+Summary!B39) -> 0.68628609 | L40: =L39*(1+Summary!H39) -> 1.1879771 | M40: =M39*(1+Summary!I39) -> 1.9912954 | N40: =MAX($K$3:K40) -> 0.99069493 | O40: =MAX($L$3:L40) -> 1.2081927 | P40: =K40/N40-1 -> -0.30726798 | Q40: =L40/O40-1 -> -0.016732115 | R40: =M40/MAX($M$3:M40)-1 -> -0.074010045 | T40: =Summary!A39 -> 37955 | U40: =Trend_Simulation!B135*Trend_Simulation!K135*4.31 -> 0.0076639005 | V40: =Trend_Simulation!C135*Trend_Simulation!L135*4.31 -> 0.014595306 | W40: =Trend_Simulation!D135*Trend_Simulation!M135*4.31 -> -0.020645117 | X40: =Trend_Simulation!E135*Trend_Simulation!N135*4.31 -> -6.9767956e-05 | Y40: =Trend_Simulation!F135*Trend_Simulation!O135*4.31 -> 0.0024523796 | Z40: =Trend_Simulation!G135*Trend_Simulation!P135*4.31 -> 0.00071768102 | AA40: =Trend_Simulation!H135*Trend_Simulation!Q135*4.31 -> 0.0018761851 | AB40: =Trend_Simulation!#REF!*Trend_Simulation!#REF!*4.31 -> #REF! | AC40: =SUM(U40:AB40) -> #REF! | AD40: =Summary!I39 -> 0.0064529451 | AE40: =AC40-AD40 -> #REF! | AF40: =LN(1+AD40) -> 0.006432214
...

Sheet Prices_Daily
B1: Commodity | C1: Commodity | D1: Commodity | E1: Commodity | F1: Commodity | G1: Commodity | H1: Commodity | I1: Bonds | J1: Bonds | K1: Bonds | L1: Equity | M1: Equity | N1: Equity | O1: Currency/Alternative | P1: Currency/Alternative | Q1: Equity | R1: Currency/Alternative | S1: Equity
A2: date | B2: GSCI Brent Crude Oil | C2: GSCI Rbob Gas | D2: GSCI Gasoil | E2: GSCI Copper | F2: GSCI Gold | G2: GSCI Soybean | H2: GSCI Cocoa | I2: Japan Gov't Bond | J2: US 10Y Gov't Bond | K2: German 10y Gov't Bond FUTURES INDEX | L2: S&P 500 Futures Excess Rtn Index | M2: Russell 2000 Futures Excess Rtn Index | N2: Nasdaq 100 Futures Excess Rtn Index | O2: SGI FX Forwards JPY/USD in USD | P2: SGI FX Forwards EUR/USD in USD | Q2: MSCI EM Excess Rtn Index | R2: Long USD Currency | S2: China Eqty Fut Index
B3: SPGCBRP INDEX | C3: SPGCHUP INDEX | D3: SPGCGOP INDEX | E3: SPGCICP INDEX | F3: SPGCGCP INDEX | G3: SPGCSOP INDEX | H3: SPGCCCP INDEX | I3: SGIXBJB INDEX | J3: SGIXBTY INDEX | K3: SGIXBRX INDEX | L3: SPXFP INDEX | M3: RTYFPE INDEX | N3: NDXNQER INDEX | O3: SGIXFJPU INDEX | P3: SGIXFEUU INDEX | Q3: MXEFERUS INDEX | R3: DXY CURNCY | S3: FRSICNEE INDEX
A4: 32874 | B4: #N/A N/A | C4: 224.418 | D4: #N/A N/A | E4: 128.555 | F4: 74.612 | G4: 220.0402 | H4: 30.1438 | I4: 1184.181 | J4: 1708.328 | K4: #N/A N/A | L4: #N/A N/A | M4: #N/A N/A | N4: #N/A N/A | O4: #N/A N/A | P4: #N/A N/A | Q4: #N/A N/A | R4: 93.16 | S4: #N/A N/A
A5: 32875 | B5: #N/A N/A | C5: 238.737 | D5: #N/A N/A | E5: 128.3133 | F5: 74.0412 | G5: 217.5838 | H5: 30.2741 | I5: 1184.181 | J5: 1706.187 | K5: #N/A N/A | L5: #N/A N/A | M5: #N/A N/A | N5: #N/A N/A | O5: #N/A N/A | P5: #N/A N/A | Q5: #N/A N/A | R5: 94.25 | S5: #N/A N/A
A6: 32876 | B6: #N/A N/A | C6: 244.334 | D6: #N/A N/A | E6: 132.4817 | F6: 72.9916 | G6: 219.7568 | H6: 29.7201 | I6: 1184.181 | J6: 1702.44 | K6: #N/A N/A | L6: #N/A N/A | M6: #N/A N/A | N6: #N/A N/A | O6: #N/A N/A | P6: #N/A N/A | Q6: #N/A N/A | R6: 94.45 | S6: #N/A N/A
A7: 32877 | B7: #N/A N/A | C7: 237.283 | D7: #N/A N/A | E7: 131.1527 | F7: 73.8018 | G7: 217.8672 | H7: 30.6326 | I7: 1175.446 | J7: 1703.511 | K7: #N/A N/A | L7: #N/A N/A | M7: #N/A N/A | N7: #N/A N/A | O7: #N/A N/A | P7: #N/A N/A | Q7: #N/A N/A | R7: 92.54 | S7: #N/A N/A
